<?xml version="1.0" encoding="UTF-8"?>
<!-- Generated by org.testng.reporters.JUnitReportReporter -->
<testsuite hostname="Sneha-MacBook-Pro.local" name="firsttestngpackage.SecondTestNGFile" tests="6" failures="1" timestamp="24 Nov 2015 22:05:35 GMT" time="3.052" errors="5">
  <testcase name="filloutEmailFld" time="0.000" classname="firsttestngpackage.SecondTestNGFile">
    <error type="java.lang.Throwable" message="Method SecondTestNGFile.filloutEmailFld()[pri:0, instance:firsttestngpackage.SecondTestNGFile@76c5e234] depends on not successfully finished methods">
      <![CDATA[java.lang.Throwable: Method SecondTestNGFile.filloutEmailFld()[pri:0, instance:firsttestngpackage.SecondTestNGFile@76c5e234] depends on not successfully finished methods
	at org.testng.internal.Invoker.invokeTestMethods(Invoker.java:1033)
	at org.testng.internal.TestMethodWorker.invokeTestMethods(TestMethodWorker.java:125)
	at org.testng.internal.TestMethodWorker.run(TestMethodWorker.java:108)
	at org.testng.TestRunner.privateRun(TestRunner.java:774)
	at org.testng.TestRunner.run(TestRunner.java:624)
	at org.testng.SuiteRunner.runTest(SuiteRunner.java:359)
	at org.testng.SuiteRunner.runSequentially(SuiteRunner.java:354)
	at org.testng.SuiteRunner.privateRun(SuiteRunner.java:312)
	at org.testng.SuiteRunner.run(SuiteRunner.java:261)
	at org.testng.SuiteRunnerWorker.runSuite(SuiteRunnerWorker.java:52)
	at org.testng.SuiteRunnerWorker.run(SuiteRunnerWorker.java:86)
	at org.testng.TestNG.runSuitesSequentially(TestNG.java:1215)
	at org.testng.TestNG.runSuitesLocally(TestNG.java:1140)
	at org.testng.TestNG.run(TestNG.java:1048)
	at firsttestngpackage.automateTestngClass.main(automateTestngClass.java:14)
]]>
    </error>
  </testcase> <!-- filloutEmailFld -->
  <testcase name="testCorrectLoginIn" time="0.000" classname="firsttestngpackage.SecondTestNGFile">
    <error type="java.lang.Throwable" message="Method SecondTestNGFile.testCorrectLoginIn()[pri:0, instance:firsttestngpackage.SecondTestNGFile@76c5e234] depends on not successfully finished methods">
      <![CDATA[java.lang.Throwable: Method SecondTestNGFile.testCorrectLoginIn()[pri:0, instance:firsttestngpackage.SecondTestNGFile@76c5e234] depends on not successfully finished methods
	at org.testng.internal.Invoker.invokeTestMethods(Invoker.java:1033)
	at org.testng.internal.TestMethodWorker.invokeTestMethods(TestMethodWorker.java:125)
	at org.testng.internal.TestMethodWorker.run(TestMethodWorker.java:108)
	at org.testng.TestRunner.privateRun(TestRunner.java:774)
	at org.testng.TestRunner.run(TestRunner.java:624)
	at org.testng.SuiteRunner.runTest(SuiteRunner.java:359)
	at org.testng.SuiteRunner.runSequentially(SuiteRunner.java:354)
	at org.testng.SuiteRunner.privateRun(SuiteRunner.java:312)
	at org.testng.SuiteRunner.run(SuiteRunner.java:261)
	at org.testng.SuiteRunnerWorker.runSuite(SuiteRunnerWorker.java:52)
	at org.testng.SuiteRunnerWorker.run(SuiteRunnerWorker.java:86)
	at org.testng.TestNG.runSuitesSequentially(TestNG.java:1215)
	at org.testng.TestNG.runSuitesLocally(TestNG.java:1140)
	at org.testng.TestNG.run(TestNG.java:1048)
	at firsttestngpackage.automateTestngClass.main(automateTestngClass.java:14)
]]>
    </error>
  </testcase> <!-- testCorrectLoginIn -->
  <testcase name="checkPageLoad" time="3.052" classname="firsttestngpackage.SecondTestNGFile">
    <failure type="java.lang.AssertionError" message="expected [Walmart] but found []">
      <![CDATA[java.lang.AssertionError: expected [Walmart] but found []
	at org.testng.Assert.fail(Assert.java:94)
	at org.testng.Assert.failNotEquals(Assert.java:496)
	at org.testng.Assert.assertEquals(Assert.java:125)
	at org.testng.Assert.assertEquals(Assert.java:178)
	at org.testng.Assert.assertEquals(Assert.java:188)
	at firsttestngpackage.SecondTestNGFile.checkPageLoad(SecondTestNGFile.java:51)
	at sun.reflect.NativeMethodAccessorImpl.invoke0(Native Method)
	at sun.reflect.NativeMethodAccessorImpl.invoke(NativeMethodAccessorImpl.java:57)
	at sun.reflect.DelegatingMethodAccessorImpl.invoke(DelegatingMethodAccessorImpl.java:43)
	at java.lang.reflect.Method.invoke(Method.java:606)
	at org.testng.internal.MethodInvocationHelper.invokeMethod(MethodInvocationHelper.java:85)
	at org.testng.internal.Invoker.invokeMethod(Invoker.java:639)
	at org.testng.internal.Invoker.invokeTestMethod(Invoker.java:816)
	at org.testng.internal.Invoker.invokeTestMethods(Invoker.java:1124)
	at org.testng.internal.TestMethodWorker.invokeTestMethods(TestMethodWorker.java:125)
	at org.testng.internal.TestMethodWorker.run(TestMethodWorker.java:108)
	at org.testng.TestRunner.privateRun(TestRunner.java:774)
	at org.testng.TestRunner.run(TestRunner.java:624)
	at org.testng.SuiteRunner.runTest(SuiteRunner.java:359)
	at org.testng.SuiteRunner.runSequentially(SuiteRunner.java:354)
	at org.testng.SuiteRunner.privateRun(SuiteRunner.java:312)
	at org.testng.SuiteRunner.run(SuiteRunner.java:261)
	at org.testng.SuiteRunnerWorker.runSuite(SuiteRunnerWorker.java:52)
	at org.testng.SuiteRunnerWorker.run(SuiteRunnerWorker.java:86)
	at org.testng.TestNG.runSuitesSequentially(TestNG.java:1215)
	at org.testng.TestNG.runSuitesLocally(TestNG.java:1140)
	at org.testng.TestNG.run(TestNG.java:1048)
	at firsttestngpackage.automateTestngClass.main(automateTestngClass.java:14)
]]>
    </failure>
  </testcase> <!-- checkPageLoad -->
  <testcase name="findSearchBar" time="0.000" classname="firsttestngpackage.SecondTestNGFile">
    <error type="java.lang.Throwable" message="Method SecondTestNGFile.findSearchBar(java.lang.String, java.lang.String, java.lang.String)[pri:10, instance:firsttestngpackage.SecondTestNGFile@76c5e234] depends on not successfully finished methods">
      <![CDATA[java.lang.Throwable: Method SecondTestNGFile.findSearchBar(java.lang.String, java.lang.String, java.lang.String)[pri:10, instance:firsttestngpackage.SecondTestNGFile@76c5e234] depends on not successfully finished methods
	at org.testng.internal.Invoker.invokeTestMethods(Invoker.java:1033)
	at org.testng.internal.TestMethodWorker.invokeTestMethods(TestMethodWorker.java:125)
	at org.testng.internal.TestMethodWorker.run(TestMethodWorker.java:108)
	at org.testng.TestRunner.privateRun(TestRunner.java:774)
	at org.testng.TestRunner.run(TestRunner.java:624)
	at org.testng.SuiteRunner.runTest(SuiteRunner.java:359)
	at org.testng.SuiteRunner.runSequentially(SuiteRunner.java:354)
	at org.testng.SuiteRunner.privateRun(SuiteRunner.java:312)
	at org.testng.SuiteRunner.run(SuiteRunner.java:261)
	at org.testng.SuiteRunnerWorker.runSuite(SuiteRunnerWorker.java:52)
	at org.testng.SuiteRunnerWorker.run(SuiteRunnerWorker.java:86)
	at org.testng.TestNG.runSuitesSequentially(TestNG.java:1215)
	at org.testng.TestNG.runSuitesLocally(TestNG.java:1140)
	at org.testng.TestNG.run(TestNG.java:1048)
	at firsttestngpackage.automateTestngClass.main(automateTestngClass.java:14)
]]>
    </error>
  </testcase> <!-- findSearchBar -->
  <testcase name="filloutPasswordFld" time="0.000" classname="firsttestngpackage.SecondTestNGFile">
    <error type="java.lang.Throwable" message="Method SecondTestNGFile.filloutPasswordFld()[pri:1, instance:firsttestngpackage.SecondTestNGFile@76c5e234] depends on not successfully finished methods">
      <![CDATA[java.lang.Throwable: Method SecondTestNGFile.filloutPasswordFld()[pri:1, instance:firsttestngpackage.SecondTestNGFile@76c5e234] depends on not successfully finished methods
	at org.testng.internal.Invoker.invokeTestMethods(Invoker.java:1033)
	at org.testng.internal.TestMethodWorker.invokeTestMethods(TestMethodWorker.java:125)
	at org.testng.internal.TestMethodWorker.run(TestMethodWorker.java:108)
	at org.testng.TestRunner.privateRun(TestRunner.java:774)
	at org.testng.TestRunner.run(TestRunner.java:624)
	at org.testng.SuiteRunner.runTest(SuiteRunner.java:359)
	at org.testng.SuiteRunner.runSequentially(SuiteRunner.java:354)
	at org.testng.SuiteRunner.privateRun(SuiteRunner.java:312)
	at org.testng.SuiteRunner.run(SuiteRunner.java:261)
	at org.testng.SuiteRunnerWorker.runSuite(SuiteRunnerWorker.java:52)
	at org.testng.SuiteRunnerWorker.run(SuiteRunnerWorker.java:86)
	at org.testng.TestNG.runSuitesSequentially(TestNG.java:1215)
	at org.testng.TestNG.runSuitesLocally(TestNG.java:1140)
	at org.testng.TestNG.run(TestNG.java:1048)
	at firsttestngpackage.automateTestngClass.main(automateTestngClass.java:14)
]]>
    </error>
  </testcase> <!-- filloutPasswordFld -->
  <testcase name="findSubmitButton" time="0.000" classname="firsttestngpackage.SecondTestNGFile">
    <error type="java.lang.Throwable" message="Method SecondTestNGFile.findSubmitButton()[pri:2, instance:firsttestngpackage.SecondTestNGFile@76c5e234] depends on not successfully finished methods">
      <![CDATA[java.lang.Throwable: Method SecondTestNGFile.findSubmitButton()[pri:2, instance:firsttestngpackage.SecondTestNGFile@76c5e234] depends on not successfully finished methods
	at org.testng.internal.Invoker.invokeTestMethods(Invoker.java:1033)
	at org.testng.internal.TestMethodWorker.invokeTestMethods(TestMethodWorker.java:125)
	at org.testng.internal.TestMethodWorker.run(TestMethodWorker.java:108)
	at org.testng.TestRunner.privateRun(TestRunner.java:774)
	at org.testng.TestRunner.run(TestRunner.java:624)
	at org.testng.SuiteRunner.runTest(SuiteRunner.java:359)
	at org.testng.SuiteRunner.runSequentially(SuiteRunner.java:354)
	at org.testng.SuiteRunner.privateRun(SuiteRunner.java:312)
	at org.testng.SuiteRunner.run(SuiteRunner.java:261)
	at org.testng.SuiteRunnerWorker.runSuite(SuiteRunnerWorker.java:52)
	at org.testng.SuiteRunnerWorker.run(SuiteRunnerWorker.java:86)
	at org.testng.TestNG.runSuitesSequentially(TestNG.java:1215)
	at org.testng.TestNG.runSuitesLocally(TestNG.java:1140)
	at org.testng.TestNG.run(TestNG.java:1048)
	at firsttestngpackage.automateTestngClass.main(automateTestngClass.java:14)
]]>
    </error>
  </testcase> <!-- findSubmitButton -->
</testsuite> <!-- firsttestngpackage.SecondTestNGFile -->
